<mujoco model="right_ur3e">
  <compiler angle="radian" meshdir="assets" autolimits="true"/>
  <worldbody>

  <body mocap="true" name="right_root_mocap">
    <geom type="sphere" size="0.04" rgba="1 0 0 1"/>
  </body>
  <body mocap="true" name="right_thumb_mocap">
    <geom type="sphere" size="0.01" rgba="0 1 0 1"/>
  </body>
  <body mocap="true" name="right_index_mocap">
    <geom type="sphere" size="0.01" rgba="0 1 0 1"/>
  </body>
  <body mocap="true" name="right_middle_mocap">
    <geom type="sphere" size="0.01" rgba="0 1 0 1"/>
  </body>
  <body mocap="true" name="right_ring_mocap">
    <geom type="sphere" size="0.01" rgba="0 1 0 1"/>
  </body>
  <body mocap="true" name="right_pinky_mocap">
    <geom type="sphere" size="0.01" rgba="0 1 0 1"/>
  </body>

  <!-- All ur3e inertial elementents (not including ability hand) are approximated identical to: 
    https://github.com/RussTedrake/drake/blob/86f833197b96aab35e4383332b2695c77c548119/manipulation/models/ur3e/ur3e.urdf.xacro#L18-L26 -->
    
    <body name="right_base" euler="2.356 3.14 -2.356" pos="-0.6 -0.21 1.45">
      <inertial mass="2.0" pos="0 0 0" diaginertia="0.0030531654454 0.0030531654454 0.005625"/>


      <geom  mesh="ur3e_scaled_42" material="mat_15" class="visual"/>
      <geom mesh="ur3e_scaled_42" class="collision"/>
      <geom  mesh="ur3e_scaled_43" material="mat_14" class="visual"/>
      <geom mesh="ur3e_scaled_43" class="collision"/>
      <geom  mesh="ur3e_scaled_44" material="mat_13" class="visual"/>
      <geom mesh="ur3e_scaled_44" class="collision"/>
      <geom  mesh="ur3e_scaled_45" material="mat_12" class="visual"/>
      <geom mesh="ur3e_scaled_45" class="collision"/>
      <geom  mesh="ur3e_scaled_46" material="mat_11" class="visual"/>
      <geom mesh="ur3e_scaled_46" class="collision"/>
      <geom  mesh="ur3e_scaled_47" material="mat_10" class="visual"/>
      <geom mesh="ur3e_scaled_47" class="collision"/>
      <geom  mesh="ur3e_scaled_56" material="mat_1" class="visual"/>
      <geom mesh="ur3e_scaled_56" class="collision"/>
      
      <body name="right_shoulder_link">
        <joint name="right_shoulder_pan_joint" class="size3" axis="0 0 -1" pos="0 0 0"/>
        <inertial mass="2.0" pos="0 0 0" diaginertia="0.008093163429399999 0.008093163429399999 0.005625"/> 


        <geom  mesh="ur3e_scaled_30" material="mat_6.002" class="visual"/>
        <geom mesh="ur3e_scaled_30" class="collision"/>
        <geom  mesh="ur3e_scaled_31" material="mat_5.002" class="visual"/>
        <geom mesh="ur3e_scaled_31" class="collision"/>
        <geom  mesh="ur3e_scaled_32" material="mat_4.002" class="visual"/>
        <geom mesh="ur3e_scaled_32" class="collision"/>
        <geom  mesh="ur3e_scaled_33" material="mat_3.002" class="visual"/>
        <geom mesh="ur3e_scaled_33" class="collision"/>
        <geom  mesh="ur3e_scaled_34" material="mat_2.002" class="visual"/>
        <geom mesh="ur3e_scaled_34" class="collision"/>
        <geom  mesh="ur3e_scaled_35" material="mat_1.002" class="visual"/>
        <geom mesh="ur3e_scaled_35" class="collision"/>

        <body name="right_upper_arm_link">
          <joint name="right_shoulder_lift_joint" class="size3" axis="0 -1 0" pos="0 -0.050 -0.152" ref="-1.571"/>
          <inertial mass="3.42" pos="0 0 0" diaginertia="0.021777126289145996 0.021777126289145996 0.00961875"/>


          <geom  mesh="ur3e_scaled_23" material="mat_7.001" class="visual"/>
          <geom mesh="ur3e_scaled_23" class="collision"/>
          <geom  mesh="ur3e_scaled_24" material="mat_6.003" class="visual"/>
          <geom mesh="ur3e_scaled_24" class="collision"/>
          <geom  mesh="ur3e_scaled_25" material="mat_5.003" class="visual"/>
          <geom mesh="ur3e_scaled_25" class="collision"/>
          <geom  mesh="ur3e_scaled_26" material="mat_4.003" class="visual"/>
          <geom mesh="ur3e_scaled_26" class="collision"/>
          <geom  mesh="ur3e_scaled_27" material="mat_3.003" class="visual"/>
          <geom mesh="ur3e_scaled_27" class="collision"/>
          <geom  mesh="ur3e_scaled_28" material="mat_2.003" class="visual"/>
          <geom mesh="ur3e_scaled_28" class="collision"/>
          <geom  mesh="ur3e_scaled_29" material="mat_1.003" class="visual"/>
          <geom mesh="ur3e_scaled_29" class="collision"/>

          <body name="right_forearm_link">
            <joint name="right_elbow_joint" class="size3_limited" axis="0 -1 0" pos="0 -0.070 -0.395"/>
            <site name="right_elbow" pos="0 -0.01 -0.395" rgba="255 0 0 255"/>
            <inertial mass="1.26" pos="0 0 0" diaginertia="0.006535617385751999 0.006535617385751999 0.00354375"/>


            <geom  mesh="ur3e_scaled_14" material="mat_8.002" class="visual"/>
            <geom mesh="ur3e_scaled_14" class="collision"/>
            <geom  mesh="ur3e_scaled_15" material="mat_7.002" class="visual"/>
            <geom mesh="ur3e_scaled_15" class="collision"/>
            <geom  mesh="ur3e_scaled_16" material="mat_6.004" class="visual"/>
            <geom mesh="ur3e_scaled_16" class="collision"/>
            <geom  mesh="ur3e_scaled_17" material="mat_5.004" class="visual"/>
            <geom mesh="ur3e_scaled_17" class="collision"/>
            <geom  mesh="ur3e_scaled_18" material="mat_4.004" class="visual"/>
            <geom mesh="ur3e_scaled_18" class="collision"/>
            <geom  mesh="ur3e_scaled_19" material="mat_3.004" class="visual"/>
            <geom mesh="ur3e_scaled_19" class="collision"/>
            <geom  mesh="ur3e_scaled_20" material="mat_2.004" class="visual"/>
            <geom mesh="ur3e_scaled_20" class="collision"/>
            <geom  mesh="ur3e_scaled_21" material="mat_1.004" class="visual"/>
            <geom mesh="ur3e_scaled_21" class="collision"/>

            <body name="right_wrist_1_link">
              <joint name="right_wrist_1_joint" class="size1" axis="0 -1 0" pos="0 -0.070 -0.6085" ref="-1.571"/>
              <inertial mass="0.8" pos="0 0 0" diaginertia="0.002084999166 0.002084999166 0.00225"/>


              <geom  mesh="ur3e_scaled_7" material="mat_7.003" class="visual"/>
              <geom mesh="ur3e_scaled_7" class="collision"/>
              <geom  mesh="ur3e_scaled_8" material="mat_6.005" class="visual"/>
              <geom mesh="ur3e_scaled_8" class="collision"/>
              <geom  mesh="ur3e_scaled_9" material="mat_5.005" class="visual"/>
              <geom mesh="ur3e_scaled_9" class="collision"/>
              <geom  mesh="ur3e_scaled_10" material="mat_4.005" class="visual"/>
              <geom mesh="ur3e_scaled_10" class="collision"/>
              <geom  mesh="ur3e_scaled_11" material="mat_3.005" class="visual"/>
              <geom mesh="ur3e_scaled_11" class="collision"/>
              <geom  mesh="ur3e_scaled_12" material="mat_2.005" class="visual"/>
              <geom mesh="ur3e_scaled_12" class="collision"/>
              <geom  mesh="ur3e_scaled_13" material="mat_1.005" class="visual"/>
              <geom mesh="ur3e_scaled_13" class="collision"/>
              
              <body name="right_wrist_2_link">
                <joint name="right_wrist_2_joint" axis="0 0 -1" class="size1" pos="0 -0.131 -0.650"/>
                <inertial mass="0.8" pos="0 0 0" diaginertia="0.002084999166 0.002084999166 0.00225"/>


                <geom  mesh="ur3e_scaled_0" material="mat_7.004" class="visual"/>
                <geom mesh="ur3e_scaled_0" class="collision"/>
                <geom  mesh="ur3e_scaled_1" material="mat_6.006" class="visual"/>
                <geom mesh="ur3e_scaled_1" class="collision"/>
                <geom  mesh="ur3e_scaled_2" material="mat_5.006" class="visual"/>
                <geom mesh="ur3e_scaled_2" class="collision"/>
                <geom  mesh="ur3e_scaled_3" material="mat_4.006" class="visual"/>
                <geom mesh="ur3e_scaled_3" class="collision"/>
                <geom  mesh="ur3e_scaled_4" material="mat_3.006" class="visual"/>
                <geom mesh="ur3e_scaled_4" class="collision"/>
                <geom  mesh="ur3e_scaled_5" material="mat_2.006" class="visual"/>
                <geom mesh="ur3e_scaled_5" class="collision"/>
                <geom  mesh="ur3e_scaled_6" material="mat_1.006" class="visual"/>
                <geom mesh="ur3e_scaled_6" class="collision"/>
                
                <body name="right_wrist_3_link">
                  <joint name="right_wrist_3_joint" class="size1" axis="0 -1 0" pos="0 -0.180 -0.694"/>
                  <inertial mass="0.35" pos="0 0 0.00665" quat="1 0 0 1" diaginertia="0.00014104994358 0.00014104994358 0.0001792"/>

                  <geom  mesh="ur3e_scaled_36" material="mat_6.001" class="visual"/>
                  <geom mesh="ur3e_scaled_36" class="collision"/>
                  <geom  mesh="ur3e_scaled_37" material="mat_5.001" class="visual"/>
                  <geom mesh="ur3e_scaled_37" class="collision"/>
                  <geom  mesh="ur3e_scaled_38" material="mat_4.001" class="visual"/>
                  <geom mesh="ur3e_scaled_38" class="collision"/>
                  <geom  mesh="ur3e_scaled_39" material="mat_3.001" class="visual"/>
                  <geom mesh="ur3e_scaled_39" class="collision"/>
                  <geom  mesh="ur3e_scaled_40" material="mat_2.001" class="visual"/>
                  <geom mesh="ur3e_scaled_40" class="collision"/>
                  <geom  mesh="ur3e_scaled_41" material="mat_1.001" class="visual"/>
                  <geom mesh="ur3e_scaled_41" class="collision"/>

                  <geom euler="1.57 0 0" pos="0 -0.222 -0.694" mesh="wrist_taller" material="mat_3.001" class="visual"/>
                  <geom euler="1.57 0 0" pos="0 -0.222 -0.694" mesh="wrist_taller" class="collision"/>

                  <site name="right_attachment_site" pos="0 -0.3 -0.694" euler="0 1.57 1.57" rgba="255 0 0 255" size="0.005 0.005 0.005"/>
                  
                  <body name="ability_right:hand_mount" pos="0 -0.258 -0.694" gravcomp="0" euler="1.5708 0 4.712">
                    <inertial pos="-0.0234454 0.00234459 0.0228783" quat="0.386518 0.610261 0.592118 0.357185" mass="0.6" diaginertia="0.00257632 0.00257632 0.00178617"/>
                    
                    <geom name="ability_right:wrist_mesh" type="mesh" contype="0" conaffinity="0" group="1" density="0" mesh="ability_right:wristmesh"/>
                    <geom name="ability_right:palm_mesh" pos="-0.0240477 0.00378125 0.0323296" quat="0.0442297 0.00061027 -0.999021 -2.70192e-05" type="mesh" contype="0" conaffinity="0" group="1" density="0" mesh="ability_right:FB_palm_ref_MIR"/>
                    <geom name="ability_right:palm_hull" pos="-0.0240477 0.00378125 0.0323296" quat="0.0442297 0.00061027 -0.999021 -2.70192e-05" type="mesh" mesh="ability_right:palm_hull_mir" class="collision"/>
                    <body name="ability_right:index_L1" pos="-0.0279216 -0.00927034 0.0958706" quat="0.685906 0.0469401 -0.714459 -0.129917" gravcomp="0">
                        <inertial pos="0.0224191 -0.000157982 -1.31987e-05" quat="-0.00406251 0.706621 0.00934715 0.707518" mass="0.00635888" diaginertia="3.81765e-06 3.69601e-06 2.96432e-07"/>
                        <joint name="ability_right:index_q1" pos="0 0 0" axis="0 0 1" limited="true" range="0 2.0944" damping="0.001" frictionloss="0.001"/>
                        <geom name="ability_right:index_mesh_1" pos="0.0384727 0.0032577 0" quat="0.999108 0 0 0.0422244" type="mesh" contype="0" conaffinity="0" group="1" density="0" mesh="ability_right:idx-F1"/>
                        <geom name="ability_right:index_hull_1" pos="0.0384727 0.0032577 0" quat="0.999108 0 0 0.0422244" type="mesh" mesh="ability_right:idx-F1-hull" class="collision"/>
                        <body name="ability_right:index_L2" pos="0.0384727 0.0032577 0" quat="0.999108 0 0 0.0422244" gravcomp="0">
                        <inertial pos="0.0133682 -0.00875392 -2.886e-05" quat="-0.161363 0.673074 0.216775 0.688434" mass="0.00645" diaginertia="2.64645e-06 2.63553e-06 1.71391e-07"/>
                        <joint name="ability_right:index_q2" pos="0 0 0" axis="0 0 1" limited="true" range="0 2.6586" damping="0.001" frictionloss="0.001"/>
                        <geom name="ability_right:index_mesh_2" pos="0.0091241 0 0" type="mesh" contype="0" conaffinity="0" group="1" density="0" mesh="ability_right:idx-F2"/>
                        <geom name="ability_right:index_hull_2" pos="0.0091241 0 0" type="mesh" mesh="ability_right:idx-F2-hull" class="collision"/>
                        <site name="right_index_L1_site" pos="0.035 -0.017 0" rgba="255 0 0 255" size="0.005 0.005 0.005"/>
                        </body>
                    </body>
                    <body name="ability_right:middle_L1" pos="-0.00841718 -0.0115172 0.0990634" quat="0.704562 0.0715738 -0.698395 -0.103508" gravcomp="0">
                        <inertial pos="0.0224191 -0.000157982 -1.31987e-05" quat="-0.00406251 0.706621 0.00934715 0.707518" mass="0.00635888" diaginertia="3.81765e-06 3.69601e-06 2.96432e-07"/>
                        <joint name="ability_right:middle_q1" pos="0 0 0" axis="0 0 1" limited="true" range="0 2.0944" damping="0.001" frictionloss="0.001"/>
                        <geom name="ability_right:middle_mesh_1" pos="0.0384727 0.0032577 0" quat="0.999108 0 0 0.0422244" type="mesh" contype="0" conaffinity="0" group="1" density="0" mesh="ability_right:idx-F1"/>
                        <geom name="ability_right:middle_hull_1" pos="0.0384727 0.0032577 0" quat="0.999108 0 0 0.0422244" type="mesh" mesh="ability_right:idx-F1-hull" class="collision"/>
                        <body name="ability_right:middle_L2" pos="0.0384727 0.0032577 0" quat="0.999108 0 0 0.0422244" gravcomp="0">
                        <inertial pos="0.0133682 -0.00875392 -2.886e-05" quat="-0.161363 0.673074 0.216775 0.688434" mass="0.00645" diaginertia="2.64645e-06 2.63553e-06 1.71391e-07"/>
                        <joint name="ability_right:middle_q2" pos="0 0 0" axis="0 0 1" limited="true" range="0 2.6586" damping="0.001" frictionloss="0.001"/>
                        <geom name="ability_right:middle_mesh_2" pos="0.0091241 0 0" type="mesh" contype="0" conaffinity="0" group="1" density="0" mesh="ability_right:idx-F2"/>
                        <geom name="ability_right:middle_hull_2" pos="0.0091241 0 0" type="mesh" mesh="ability_right:idx-F2-hull" class="collision"/>
                        <site name="right_middle_L1_site" pos="0.035 -0.017 0" rgba="255 0 0 255" size="0.005 0.005 0.005"/>
                        </body>
                    </body>
                    <body name="ability_right:ring_L1" pos="0.0117529 -0.0103946 0.0967038" quat="0.721351 0.0986547 -0.681173 -0.0769649" gravcomp="0">
                        <inertial pos="0.0224191 -0.000157982 -1.31987e-05" quat="-0.00406251 0.706621 0.00934715 0.707518" mass="0.00635888" diaginertia="3.81765e-06 3.69601e-06 2.96432e-07"/>
                        <joint name="ability_right:ring_q1" pos="0 0 0" axis="0 0 1" limited="true" range="0 2.0944" damping="0.001" frictionloss="0.001"/>
                        <geom name="ability_right:ring_mesh_1" pos="0.0384727 0.0032577 0" quat="0.999108 0 0 0.0422244" type="mesh" contype="0" conaffinity="0" group="1" density="0" mesh="ability_right:idx-F1"/>
                        <geom name="ability_right:ring_hull_1" pos="0.0384727 0.0032577 0" quat="0.999108 0 0 0.0422244" type="mesh" mesh="ability_right:idx-F1-hull" class="collision"/>
                        <body name="ability_right:ring_L2" pos="0.0384727 0.0032577 0" quat="0.999108 0 0 0.0422244" gravcomp="0">
                        <inertial pos="0.0133682 -0.00875392 -2.886e-05" quat="-0.161363 0.673074 0.216775 0.688434" mass="0.00645" diaginertia="2.64645e-06 2.63553e-06 1.71391e-07"/>
                        <joint name="ability_right:ring_q2" pos="0 0 0" axis="0 0 1" limited="true" range="0 2.6586" damping="0.001" frictionloss="0.001"/>
                        <geom name="ability_right:ring_mesh_2" pos="0.0091241 0 0" type="mesh" contype="0" conaffinity="0" group="1" density="0" mesh="ability_right:idx-F2"/>
                        <geom name="ability_right:ring_hull_2" pos="0.0091241 0 0" type="mesh" mesh="ability_right:idx-F2-hull" class="collision"/> 
                        <site name="right_ring_L1_site" pos="0.035 -0.017 0" rgba="255 0 0 255" size="0.005 0.005 0.005"/>
                        </body>
                    </body>
                    <body name="ability_right:pinky_L1" pos="0.0308633 -0.00716283 0.0907346" quat="0.719226 0.122363 -0.681748 -0.0544096" gravcomp="0">
                        <inertial pos="0.0224191 -0.000157982 -1.31987e-05" quat="-0.00406251 0.706621 0.00934715 0.707518" mass="0.00635888" diaginertia="3.81765e-06 3.69601e-06 2.96432e-07"/>
                        <joint name="ability_right:pinky_q1" pos="0 0 0" axis="0 0 1" limited="true" range="0 2.0944" damping="0.001" frictionloss="0.001"/>
                        <geom name="ability_right:pinky_mesh_1" pos="0.0384727 0.0032577 0" quat="0.999108 0 0 0.0422244" type="mesh" contype="0" conaffinity="0" group="1" density="0" mesh="ability_right:idx-F1"/>
                        <geom name="ability_right:pinky_hull_1" pos="0.0384727 0.0032577 0" quat="0.999108 0 0 0.0422244" type="mesh" mesh="ability_right:idx-F1-hull" class="collision"/>
                        <body name="ability_right:pinky_L2" pos="0.0384727 0.0032577 0" quat="0.999108 0 0 0.0422244" gravcomp="0">
                        <inertial pos="0.0133682 -0.00875392 -2.886e-05" quat="-0.161363 0.673074 0.216775 0.688434" mass="0.00645" diaginertia="2.64645e-06 2.63553e-06 1.71391e-07"/>
                        <joint name="ability_right:pinky_q2" pos="0 0 0" axis="0 0 1" limited="true" range="0 2.6586" damping="0.001" frictionloss="0.001"/>
                        <geom name="ability_right:pinky_mesh_2" pos="0.0091241 0 0" type="mesh" contype="0" conaffinity="0" group="1" density="0" mesh="ability_right:idx-F2"/>
                        <geom name="ability_right:pinky_hull_2" pos="0.0091241 0 0" type="mesh" mesh="ability_right:idx-F2-hull" class="collision"/>
                        <site name="right_pinky_L1_site" pos="0.035 -0.017 0" rgba="255 0 0 255" size="0.005 0.005 0.005"/>
                        </body>
                    </body>
                    <body name="ability_right:thumb_L1" pos="-0.0240477 0.00378125 0.0323296" quat="-0.0947972 0.0440301 -0.00419696 0.994514" gravcomp="0">
                        <inertial pos="0.014606 -0.00189085 -0.00311554" quat="0.306728 0.531258 0.293089 0.733336" mass="0.00268342" diaginertia="8.14795e-07 7.42718e-07 1.14409e-07"/>
                        <joint name="ability_right:thumb_q1" pos="0 0 0" axis="0 0 1" limited="true" range="-2.0944 0" damping="0.001" frictionloss="0.001"/>
                        <geom name="ability_right:thumb_mesh_1" pos="0.0278284 0 0.0147507" quat="0.608761 0.793353 0 0" type="mesh" contype="0" conaffinity="0" group="1" density="0" mesh="ability_right:thumb-F1-MIR"/>
                        <geom name="ability_right:thumb_hull_1" pos="0.0278284 0 0.0147507" quat="0.608761 0.793353 0 0" type="mesh" mesh="ability_right:thumb-F1-MIR-hull" class="collision"/>
                        <body name="ability_right:thumb_L2" pos="0.0278284 0 0.0147507" quat="0.608761 0.793353 0 0" gravcomp="0">
                        <inertial pos="0.0300205 0.00559476 -0.00415044" quat="0.00721249 0.656735 -0.223684 0.720148" mass="0.0055" diaginertia="1.80207e-05 1.70892e-05 2.87855e-06"/>
                        <joint name="ability_right:thumb_q2" pos="0 0 0" axis="0 0 1" limited="true" range="0 2.0944" damping="0.001" frictionloss="0.001"/>
                        <geom name="ability_right:thumb_mesh_2" pos="0.0651867 0.0233402 0.00393483" quat="3.21978e-07 -0.985259 -0.171069 5.59046e-08" type="mesh" contype="0" conaffinity="0" group="1" density="0" mesh="ability_right:thumb-F2"/>
                        <geom name="ability_right:thumb_hull_2" pos="0.0651867 0.0233402 0.00393483" quat="3.21978e-07 -0.985259 -0.171069 5.59046e-08" type="mesh" mesh="ability_right:thumb-F2-hull" class="collision"/>
                        <site name="right_thumb_L1_site" pos="0.065 0.02 -0.01" rgba="255 0 0 255" size="0.005 0.005 0.005"/>
                        </body>
                    </body>
                  </body>
                  
                </body>
              </body>
            </body>
          </body>
        </body>
      </body>
    </body>
  </worldbody>

  <!-- UR3e motors have gear=max_effort, with ctrlrange=-1 1, values from:
  https://github.com/ros-industrial/universal_robot/blob/6507bb6756d0065d49b76230ff55f875f099a827/ur_description/config/ur3e/joint_limits.yaml -->

  <actuator>
    <motor name="right_shoulder_pan" ctrlrange="-1 1" joint="right_shoulder_pan_joint" gear="56"/>
    <motor name="right_shoulder_lift" ctrlrange="-1 1" joint="right_shoulder_lift_joint" gear="56"/>
    <motor name="right_elbow" ctrlrange="-1 1" joint="right_elbow_joint" gear="28"/>
    <motor name="right_wrist_1" ctrlrange="-1 1" joint="right_wrist_1_joint" gear="12"/>
    <motor name="right_wrist_2" ctrlrange="-1 1" joint="right_wrist_2_joint" gear="12"/>
    <motor name="right_wrist_3" ctrlrange="-1 1" joint="right_wrist_3_joint" gear="12"/>

    
    
    
    
    <position name="ability_right:index_q1" joint="ability_right:index_q1"             kp="0.08"/>
    <!-- <position name="ability_right:index_q2" joint="ability_right:index_q2" kp="0.08"/> -->
    <position name="ability_right:middle_q1" joint="ability_right:middle_q1" kp="0.08"/>
    <!-- <position name="ability_right:middle_q2" joint="ability_right:middle_q2" kp="0.08"/> -->
    <position name="ability_right:ring_q1" joint="ability_right:ring_q1" kp="0.08"/>
    <!-- <position name="ability_right:ring_q2" joint="ability_right:ring_q2" kp="0.08"/> -->
    <position name="ability_right:pinky_q1" joint="ability_right:pinky_q1" kp="0.08"/>
    <!-- <position name="ability_right:pinky_q2" joint="ability_right:pinky_q2" kp="0.08"/> -->
    <position name="ability_right:thumb_q1" joint="ability_right:thumb_q1" kp="0.05"/>
    <position name="ability_right:thumb_q2" joint="ability_right:thumb_q2" kp="0.05"/>
  </actuator>

  <sensor>
    <jointpos name="right_shoulder_pan_joint" joint="right_shoulder_pan_joint"/>
    <jointpos name="right_shoulder_lift_joint" joint="right_shoulder_lift_joint"/>
    <jointpos name="right_elbow_joint" joint="right_elbow_joint"/>
    <jointpos name="right_wrist_1_joint" joint="right_wrist_1_joint"/>
    <jointpos name="right_wrist_2_joint" joint="right_wrist_2_joint"/>
    <jointpos name="right_wrist_3_joint" joint="right_wrist_3_joint"/>

    <jointvel name="right_shoulder_pan_joint_vel" joint="right_shoulder_pan_joint"/>
    <jointvel name="right_shoulder_lift_joint_vel" joint="right_shoulder_lift_joint"/>
    <jointvel name="right_elbow_joint_vel" joint="right_elbow_joint"/>
    <jointvel name="right_wrist_1_joint_vel" joint="right_wrist_1_joint"/>
    <jointvel name="right_wrist_2_joint_vel" joint="right_wrist_2_joint"/>
    <jointvel name="right_wrist_3_joint_vel" joint="right_wrist_3_joint"/>
  </sensor>

    <equality>
    <!-- Drives joint1 to equal joint2  -->
    <!-- bestfit coefficients:  [1.05851325 0.72349796] -->
    <!-- linfit_q2 = (q1 * c[0] + c[1]) -->
    <joint joint1="ability_right:index_q2" joint2="ability_right:index_q1"        polycoef="0.72349796 1.05851325  0 0 0"/>
    <joint joint1="ability_right:middle_q2" joint2="ability_right:middle_q1"      polycoef="0.72349796 1.05851325  0 0 0"/>
    <joint joint1="ability_right:ring_q2" joint2="ability_right:ring_q1"          polycoef="0.72349796 1.05851325  0 0 0"/> 
    <joint joint1="ability_right:pinky_q2" joint2="ability_right:pinky_q1"        polycoef="0.72349796 1.05851325  0 0 0"/>
  </equality>

</mujoco>
